<?xml version="1.0"?>

<robot name="learnbotics_l" xmlns:xacro="http://ros.org/wiki/xacro">
  <link name="base_link">
  </link>


  <!-- ### BODY AND JOINT ###-->
  <link name="Body">
    <visual>
      <origin rpy="0 0 0" xyz="0 0 0"/>
      <geometry>
        <mesh filename="package://learnbotics_l/meshes/Capa.stl"/>
      </geometry>
    </visual>

    <collision>
      <origin rpy="0 0 0" xyz="0 0 0"/>
      <geometry>
        <mesh filename="package://learnbotics_l/meshes/Capa.stl"/>
      </geometry>
    </collision>

    <inertial>
      <origin rpy="0 0 0" xyz="0 0 0"/>
      <mass value="0.327"/>
      <inertia ixx="0.00063300" ixy="0.00005131" ixz="0.00000034" iyy="0.00120200" iyz="0" izz="0.00102900"/>
    </inertial>
  </link>

  <joint name="base_to_Body" type="fixed">
    <parent link="base_link"/>
    <child link="Body"/>
    <origin rpy="1.571 0 0" xyz="0 0 0" />
  </joint>


  <!-- ### LEFT WHEEL AND JOINT ### -->
  <link name="Left_Wheel">
    <visual>
      <origin rpy="1.571 0 0" xyz="0 0 0"/>
      <geometry>
        <mesh filename="package://learnbotics_l/meshes/Wheel.stl"/>
      </geometry>
    </visual>

    <collision>
      <origin rpy="1.571 0 0" xyz="0 0 0"/>
      <geometry>
        <mesh filename="package://learnbotics_l/meshes/Wheel.stl"/>
      </geometry>
    </collision>

    <inertial>
      <origin rpy="1.571 0 0" xyz="0 0 0"/>
      <mass value="0.027"/>
      <inertia ixx="0.00001095" ixy="0" ixz="0" iyy="0.00001095" iyz="0" izz="0.00002138"/>
    </inertial>
  </link>

  <joint name="Body_to_Left_Wheel" type="continuous">
    <parent link="Body"/>
    <child link="Left_Wheel"/>
    <origin rpy="1.571 0 0" xyz="-0.057649 -0.034678 -0.059005" />
    <axis xyz="0 -1 0" />
  </joint>


  <!-- ### RIGHT WHEEL AND JOINT ### -->
  <link name="Right_Wheel">
    <visual>
      <origin rpy="-1.571 0 0" xyz="0 0 0"/>
      <geometry>
        <mesh filename="package://learnbotics_l/meshes/Wheel.stl"/>
      </geometry>
    </visual>

    <collision>
      <origin rpy="-1.571 0 0" xyz="0 0 0"/>
      <geometry>
        <mesh filename="package://learnbotics_l/meshes/Wheel.stl"/>
      </geometry>
    </collision>

    <inertial>
      <origin rpy="-1.571 0 0" xyz="0 0 0"/>
      <mass value="0.027"/>
      <inertia ixx="0.00001095" ixy="0" ixz="0" iyy="0.00001095" iyz="0" izz="0.00002138"/>
    </inertial>
  </link>

  <joint name="Body_to_Right_Wheel" type="continuous">
    <parent link="Body"/>
    <child link="Right_Wheel"/>
    <origin rpy="1.571 0 0" xyz="-0.057649 -0.034678 0.059005" />
    <axis xyz="0 -1 0" />
  </joint>


  <!-- ### 3 SPHERES AND JOINTS ### -->
  <link name="Sphere">
    <visual>
      <origin rpy="0 0 0" xyz="0 0 0"/>
      <geometry>
        <mesh filename="package://learnbotics_l/meshes/Sphere.stl"/>
      </geometry>
    </visual>

    <collision>
      <origin rpy="0 0 0" xyz="0 0 0"/>
      <geometry>
        <mesh filename="package://learnbotics_l/meshes/Sphere.stl"/>
      </geometry>
    </collision>

    <inertial>
      <origin rpy="0 0 0" xyz="0 0 0"/>
      <mass value="0.01"/>
      <inertia ixx="0.00000042" ixy="0" ixz="0" iyy="0.00000042" iyz="0" izz="0.00000042"/>
    </inertial>
  </link>

  <joint name="Body_to_Sphere" type="continuous">
    <parent link="Body"/>
    <child link="Sphere"/>
    <origin rpy="0 0 0" xyz="0.028278 -0.064603 0.000136" />
    <axis xyz="0 0 -1" />
  </joint>

  <link name="Sphere_2">
    <visual>
      <origin rpy="0 0 0" xyz="0 0 0"/>
      <geometry>
        <mesh filename="package://learnbotics_l/meshes/Sphere.stl"/>
      </geometry>
    </visual>

    <collision>
      <origin rpy="0 0 0" xyz="0 0 0"/>
      <geometry>
        <mesh filename="package://learnbotics_l/meshes/Sphere.stl"/>
      </geometry>
    </collision>

    <inertial>
      <origin rpy="0 0 0" xyz="0 0 0"/>
      <mass value="0.01"/>
      <inertia ixx="0.00000042" ixy="0" ixz="0" iyy="0.00000042" iyz="0" izz="0.00000042"/>
    </inertial>
  </link>

  <joint name="Sphere_to_Sphere_2" type="continuous">
    <parent link="Sphere"/>
    <child link="Sphere_2"/>
    <origin rpy="0 0 0" xyz="0 0 0" />
    <axis xyz="0 -1 0" />
  </joint>

  <link name="Sphere_3">
    <visual>
      <origin rpy="0 0 0" xyz="0 0 0"/>
      <geometry>
        <mesh filename="package://learnbotics_l/meshes/Sphere.stl"/>
      </geometry>
    </visual>

    <collision>
      <origin rpy="0 0 0" xyz="0 0 0"/>
      <geometry>
        <mesh filename="package://learnbotics_l/meshes/Sphere.stl"/>
      </geometry>
    </collision>

    <inertial>
      <origin rpy="0 0 0" xyz="0 0 0"/>
      <mass value="0.01"/>
      <inertia ixx="0.00000042" ixy="0" ixz="0" iyy="0.00000042" iyz="0" izz="0.00000042"/>
    </inertial>
  </link>

  <joint name="Sphere_2_to_Sphere_3" type="continuous">
    <parent link="Sphere_2"/>
    <child link="Sphere_3"/>
    <origin rpy="0 0 0" xyz="0 0 0" />
    <axis xyz="-1 0 0" />
  </joint>

    
  <!-- ### LIDAR AND JOINT ### -->
  <link name="Lidar">
    <visual>
      <origin rpy="0 0 0" xyz="0 0 0"/>
      <geometry>
        <mesh filename="package://learnbotics_l/meshes/Lidar.stl"/>
      </geometry>
    </visual>

    <collision>
      <origin rpy="0 0 0" xyz="0 0 0"/>
      <geometry>
        <mesh filename="package://learnbotics_l/meshes/Lidar.stl"/>
      </geometry>
    </collision>

    <inertial>
      <origin rpy="0 0 0" xyz="0 0 0"/>
      <mass value="0.031"/>
      <inertia ixx="1.184e-5" ixy="-4.274e-11" ixz="-2.070e-12" iyy="1.206e-5" iyz="0" izz="4.594e-6"/>
    </inertial>
  </link>

  <joint name="Body_to_Lidar" type="fixed">
    <parent link="Body"/>
    <child link="Lidar"/>
    <origin rpy="-1.571 1.571 0" xyz="0 0.07911977 0"/>
  </joint>

  <!-- # ray sensor (LIDAR PLUGIN) # -->
  <gazebo reference="Lidar">
    <sensor type="ray" name="head_hokuyo_sensor">
      <pose>0 0 0 0 0 0</pose>
      <visualize>false</visualize>
      <update_rate>20</update_rate>
      <ray>
        <scan>
          <horizontal>
            <samples>720</samples>
            <resolution>1</resolution>
            <min_angle>3.1415</min_angle>
            <max_angle>6.2831</max_angle>
          </horizontal>
          <vertical>
            <samples>720</samples>
            <resolution>1</resolution>
            <min_angle>3.1415</min_angle>
            <max_angle>6.2831</max_angle>
          </vertical>
        </scan>
        <range>
          <min>0.10</min>
          <max>10.0</max>
          <resolution>0.01</resolution>
        </range>
        <noise>
          <type>gaussian</type>
          <mean>0.0</mean>
          <stddev>0.01</stddev>
        </noise>
      </ray>
      <plugin name="gazebo_ros_laser_controller" filename="libgazebo_ros_velodyne_laser.so">
        <topicName>/learnbotics_l/laser/scan</topicName>
        <frameName>Lidar</frameName>
        <min_range>0.19</min_range>
        <max_range>130</max_range>
      </plugin>
    </sensor>
  </gazebo>


  <!-- ### CAMERA, JOINT AND PLUGIN ### -->
  <link name="Camera">
    <visual>
      <origin rpy="0 0 0" xyz="0 0 0"/>
      <geometry>
        <mesh filename="package://learnbotics_l/meshes/Camera.stl"/>
      </geometry>
    </visual>

    <collision>
      <origin rpy="0 0 0" xyz="0 0 0"/>
      <geometry>
        <mesh filename="package://learnbotics_l/meshes/Camera.stl"/>
      </geometry>
    </collision>

    <inertial>
      <origin rpy="0 0 0" xyz="0 0 0"/>
      <mass value="0.002"/>
      <inertia ixx="1.397e-7" ixy="0" ixz="-2.070e-12" iyy="1.512e-7" iyz="1.844e-9" izz="7.943e-8"/>
    </inertial>
  </link>

  <joint name="Body_to_Camera" type="fixed">
    <parent link="Body"/>
    <child link="Camera"/>
    <origin rpy="-1.571 0 0" xyz="0.07456502 0.02996464 0.00016464"/>
  </joint>

  <gazebo reference="Camera">
    <sensor type="camera" name="camera_top">
      <update_rate>30.0</update_rate>
      <camera name="head">
        <horizontal_fov>1.3962634</horizontal_fov>
        <image>
          <width>1366</width>
          <height>768</height>
          <format>R8G8B8</format>
        </image>
        <clip>
          <near>0.02</near>
          <far>300</far>
        </clip>
      </camera>
      <plugin name="camera_controller" filename="libgazebo_ros_camera.so">
        <alwaysOn>true</alwaysOn>
        <updateRate>0.0</updateRate>
        <cameraName>diff/camera_top</cameraName>
        <imageTopicName>image_raw</imageTopicName>
        <cameraInfoTopicName>camera_info</cameraInfoTopicName>
        <frameName>Camera</frameName>
        <hackBaseline>0.07</hackBaseline>
        <distortionK1>0.0</distortionK1>
        <distortionK2>0.0</distortionK2>
        <distortionK3>0.0</distortionK3>
        <distortionT1>0.0</distortionT1>
        <distortionT2>0.0</distortionT2>
      </plugin>
    </sensor>
  </gazebo>


  <!-- ### DIFERENTIAL DRIVE PLUGIN ### -->
  <gazebo>
    <plugin name="gazebo_ros_control" filename="libgazebo_ros_diff_drive.so">
      <robotNamespace>/</robotNamespace>
      <legacyModeNS>true</legacyModeNS>
      <alwaysOn>true</alwaysOn>
      <legacyMode>false</legacyMode>
      <updateRate>40</updateRate>
      <leftJoint>Body_to_Left_Wheel</leftJoint>
      <rightJoint>Body_to_Right_Wheel</rightJoint>
      <wheelSeparation>0.10966201</wheelSeparation>
      <wheelDiameter>0.075</wheelDiameter>
      <torque>20</torque>
      <commandTopic>cmd_vel</commandTopic>
      <odometryTopic>odom</odometryTopic>
      <odometryFrame>odom</odometryFrame>
      <publishWheelTF>true</publishWheelTF>
      <publishOdomTF>true</publishOdomTF>
      <publishWheelJointState>true</publishWheelJointState>
      <robotBaseFrame>base_link</robotBaseFrame>
    </plugin>
  </gazebo>

</robot>







